Workbook

Sheet Database
A1: ингредиенты | C1: жиры | E1: сухое | F1: сухие | G1: прочие | I1: цена
B2: сахара | C2: раст.жиры и молочные | D2: масло какао | E2: молоко | F2: какао | G2: сухие | H2: вода | J2: сладость
A6: Alco lichi | H6: 0.79 | I6: 0
A7: alcool 40% | H7: 0.6 | I7: 270
A8: alcool 50% | H8: 0.5 | I8: 180
A9: banana puree | B9: 0.25 | G9: 0.18 | H9: 0.57 | I9: 0 | J9: 0.25
A10: Barry Alto el Sol | B10: 0.35 | D10: 0.37 | F10: 0.27 | I10: 0 | J10: 0.35
A11: Barry Blanc Satin | B11: 0.49 | C11: 0.04 | D11: 0.29 | E11: 0.16 | I11: 0 | J11: 0.49
A12: Barry Cuba | B12: 0.3 | D12: 0.41 | F12: 0.28 | I12: 0 | J12: 0.3
A13: Barry Excellence | B13: 0.45 | D13: 0.34 | F13: 0.18 | I13: 0 | J13: 0.45
A14: Barry Extra bitter | B14: 0.35 | D14: 0.41 | F14: 0.23 | I14: 0 | J14: 0.35
A15: Barry Fleur de Cao | B15: 0.3 | D15: 0.42 | F15: 0.27 | I15: 0 | J15: 0.3
A16: Barry Ghana | B16: 0.39 | C16: 0.06 | D16: 0.33 | E16: 0.15 | F16: 0.07 | I16: 0 | J16: 0.39
A17: Barry Lactee Superieure | B17: 0.4 | C17: 0.06 | D17: 0.32 | E17: 0.16 | F17: 0.06 | I17: 0 | J17: 0.4
A18: Barry Mexique | B18: 0.34 | D18: 0.37 | F18: 0.28 | I18: 0 | J18: 0.34
A19: Barry Papouasie | B19: 0.41 | C19: 0.06 | D19: 0.3 | E19: 0.17 | F19: 0.05 | I19: 0 | J19: 0.41
A20: Barry Saint Dominique | B20: 0.3 | D20: 0.42 | F20: 0.27 | I20: 0 | J20: 0.3
A21: Barry Tanzanie | B21: 0.25 | D21: 0.45 | F21: 0.29 | I21: 0 | J21: 0.25
A22: Barry Zephyr | B22: 0.4 | C22: 0.06 | D22: 0.34 | E22: 0.2 | I22: 0 | J22: 0.4
A23: bergamote | B23: 0.035 | G23: 0.055 | H23: 0.91 | I23: 0 | J23: 0.035
A24: butter noisette | C24: 0.99 | H24: 0.01 | I24: 0
A25: butter anhydrous 28 | C25: 0.98 | E25: 0.02 | I25: 0
A26: butter cacao | D26: 1 | I26: 0
A27: butter fresh | C27: 0.82 | E27: 0.02 | H27: 0.16 | I27: 0
A28: cacao-barry Excellence | B28: 0.43 | D28: 0.39 | F28: 0.18 | I28: 0 | J28: 0.43
A29: callebaut 60/40/38 | B29: 0.38 | D29: 0.388 | F29: 0.232 | I29: 0 | J29: 0.38
A30: callebaut 70/30/38 | B30: 0.265 | D30: 0.387 | F30: 0.34 | I30: 0 | J30: 0.265
A31: callebaut 811 | B31: 0.44 | D31: 0.353 | F31: 0.185 | I31: 0 | J31: 0.44
A32: callebaut 823 | B32: 0.42 | C32: 0.06 | D32: 0.3 | E32: 0.165 | F32: 0.03 | I32: 0 | J32: 0.42
A33: callebaut arriba | B33: 0.328 | C33: 0.063 | D33: 0.262 | E33: 0.214 | F33: 0.066 | I33: 0 | J33: 0.328
A34: callebaut cocoa massa | D34: 0.55 | F34: 0.45 | I34: 0
A35: callebaut equateur | B35: 0.265 | D35: 0.414 | F35: 0.31 | I35: 0 | J35: 0.265
A36: callebaut madagascar | B36: 0.295 | D36: 0.397 | F36: 0.278 | I36: 0 | J36: 0.295
A37: callebaut sao thomé | B37: 0.27 | D37: 0.38 | F37: 0.29 | I37: 0 | J37: 0.27
A38: callebaut velvet | B38: 0.415 | C38: 0.065 | D38: 0.345 | E38: 0.175 | I38: 0 | J38: 0.415
A39: callebaut W2 | B39: 0.465 | C39: 0.06 | D39: 0.295 | E39: 0.175 | I39: 0 | J39: 0.465
A40: cream 35% | B40: 0.005 | C40: 0.35 | E40: 0.025 | H40: 0.62 | I40: 0
A41: cream 38% | B41: 0.005 | C41: 0.38 | E41: 0.025 | H41: 0.59 | I41: 0
A42: fruit puree абрикос | B42: 0.171 | H42: 0.775 | I42: 0 | J42: 0.17
A43: fruit puree облепиха | G43: 0.08 | H43: 0.92 | I43: 0
...

Sheet calculator
D1: 2 | E1: 3 | F1: 4 | G1: 5 | H1: 6 | I1: 7 | J1: 8
B2: =Database!A4 -> 0 | C2: название рецепта
A3: =#REF! -> #REF! | B3: =Database!A5 -> 0 | E3: % | G3: жиры | I3: сс.м | J3: какао | K3: прочие | L3: вода | M3: цена | N3: сладость
A4: =#REF! -> #REF! | B4: =Database!A6 -> Alco lichi | D4: количество | F4: сахар | G4: 28-32 | H4: м.к. | J4: сухое | K4: сухие | N4: сладость
A5: =#REF! -> #REF! | B5: =Database!A7 -> alcool 40% | E5: =D5/$D$30 -> 0 | F5: =IF(ISERROR(VLOOKUP($C5,Database!$A:$I,D$1,FALSE)*$E5),0,VLOOKUP($C5,Database!$A:$I,D$1,FALSE)*$E5) -> 0 | G5: =IF(ISERROR(VLOOKUP($C5,Database!$A:$I,E$1,FALSE)*$E5),0,VLOOKUP($C5,Database!$A:$I,E$1,FALSE)*$E5) -> 0 | H5: =IF(ISERROR(VLOOKUP($C5,Database!$A:$I,F$1,FALSE)*$E5),0,VLOOKUP($C5,Database!$A:$I,F$1,FALSE)*$E5) -> 0 | I5: =IF(ISERROR(VLOOKUP($C5,Database!$A:$I,G$1,FALSE)*$E5),0,VLOOKUP($C5,Database!$A:$I,G$1,FALSE)*$E5) -> 0 | J5: =IF(ISERROR(VLOOKUP($C5,Database!$A:$I,H$1,FALSE)*$E5),0,VLOOKUP($C5,Database!$A:$I,H$1,FALSE)*$E5) -> 0 | K5: =IF(ISERROR(VLOOKUP($C5,Database!$A:$I,I$1,FALSE)*$E5),0,VLOOKUP($C5,Database!$A:$I,I$1,FALSE)*$E5) -> 0 | L5: =IF(ISERROR(VLOOKUP($C5,Database!$A:$I,J$1,FALSE)*$E5),0,VLOOKUP($C5,Database!$A:$I,J$1,FALSE)*$E5) -> 0 | M5: =IF(ISERROR(VLOOKUP($C5,Database!$A:$I,K$1,FALSE)*$E5),0,VLOOKUP($C5,Database!$A:$I,K$1,FALSE)*$E5) -> 0 | N5: =IF(ISERROR(VLOOKUP($C5,Database!$A:$J,10,FALSE)),0,VLOOKUP($C5,Database!$A:$J,10,FALSE)*$E5) -> 0
A6: =#REF! -> #REF! | B6: =Database!A8 -> alcool 50% | C6: Сливки 33% | D6: 12 | E6: =D6/$D$30 -> 0.019775873 | F6: =IF(ISERROR(VLOOKUP($C6,Database!$A:$I,D$1,FALSE)*$E6),0,VLOOKUP($C6,Database!$A:$I,D$1,FALSE)*$E6) -> 0 | G6: =IF(ISERROR(VLOOKUP($C6,Database!$A:$I,E$1,FALSE)*$E6),0,VLOOKUP($C6,Database!$A:$I,E$1,FALSE)*$E6) -> 0.0065260382 | H6: =IF(ISERROR(VLOOKUP($C6,Database!$A:$I,F$1,FALSE)*$E6),0,VLOOKUP($C6,Database!$A:$I,F$1,FALSE)*$E6) -> 0 | I6: =IF(ISERROR(VLOOKUP($C6,Database!$A:$I,G$1,FALSE)*$E6),0,VLOOKUP($C6,Database!$A:$I,G$1,FALSE)*$E6) -> 0.00049439684 | J6: =IF(ISERROR(VLOOKUP($C6,Database!$A:$I,H$1,FALSE)*$E6),0,VLOOKUP($C6,Database!$A:$I,H$1,FALSE)*$E6) -> 0 | K6: =IF(ISERROR(VLOOKUP($C6,Database!$A:$I,I$1,FALSE)*$E6),0,VLOOKUP($C6,Database!$A:$I,I$1,FALSE)*$E6) -> 0 | L6: =IF(ISERROR(VLOOKUP($C6,Database!$A:$I,J$1,FALSE)*$E6),0,VLOOKUP($C6,Database!$A:$I,J$1,FALSE)*$E6) -> 0.01212261 | M6: =IF(ISERROR(VLOOKUP($C6,Database!$A:$I,K$1,FALSE)*$E6),0,VLOOKUP($C6,Database!$A:$I,K$1,FALSE)*$E6) -> 0 | N6: =IF(ISERROR(VLOOKUP($C6,Database!$A:$J,10,FALSE)),0,VLOOKUP($C6,Database!$A:$J,10,FALSE)*$E6) -> 0
A7: =#REF! -> #REF! | B7: =Database!A9 -> banana puree | C7: sugar inverted | D7: 0.8 | E7: =D7/$D$30 -> 0.0013183916 | F7: =IF(ISERROR(VLOOKUP(#REF!,Database!$A:$I,D$1,FALSE)*$E7),0,VLOOKUP(#REF!,Database!$A:$I,D$1,FALSE)*$E7) -> 0 | G7: =IF(ISERROR(VLOOKUP(#REF!,Database!$A:$I,E$1,FALSE)*$E7),0,VLOOKUP(#REF!,Database!$A:$I,E$1,FALSE)*$E7) -> 0 | H7: =IF(ISERROR(VLOOKUP(#REF!,Database!$A:$I,F$1,FALSE)*$E7),0,VLOOKUP(#REF!,Database!$A:$I,F$1,FALSE)*$E7) -> 0 | I7: =IF(ISERROR(VLOOKUP(#REF!,Database!$A:$I,G$1,FALSE)*$E7),0,VLOOKUP(#REF!,Database!$A:$I,G$1,FALSE)*$E7) -> 0 | J7: =IF(ISERROR(VLOOKUP(#REF!,Database!$A:$I,H$1,FALSE)*$E7),0,VLOOKUP(#REF!,Database!$A:$I,H$1,FALSE)*$E7) -> 0 | K7: =IF(ISERROR(VLOOKUP(#REF!,Database!$A:$I,I$1,FALSE)*$E7),0,VLOOKUP(#REF!,Database!$A:$I,I$1,FALSE)*$E7) -> 0 | L7: =IF(ISERROR(VLOOKUP(#REF!,Database!$A:$I,J$1,FALSE)*$E7),0,VLOOKUP(#REF!,Database!$A:$I,J$1,FALSE)*$E7) -> 0 | M7: =IF(ISERROR(VLOOKUP(#REF!,Database!$A:$I,K$1,FALSE)*$E7),0,VLOOKUP(#REF!,Database!$A:$I,K$1,FALSE)*$E7) -> 0 | N7: =IF(ISERROR(VLOOKUP(#REF!,Database!$A:$J,10,FALSE)),0,VLOOKUP(#REF!,Database!$A:$J,10,FALSE)*$E7) -> 0
A8: =#REF! -> #REF! | B8: =Database!A10 -> Barry Alto el Sol | C8: glucose | D8: 3 | E8: =D8/$D$30 -> 0.0049439684 | F8: =IF(ISERROR(VLOOKUP($C7,Database!$A:$I,D$1,FALSE)*$E8),0,VLOOKUP($C7,Database!$A:$I,D$1,FALSE)*$E8) -> 0.0040540541 | G8: =IF(ISERROR(VLOOKUP($C7,Database!$A:$I,E$1,FALSE)*$E8),0,VLOOKUP($C7,Database!$A:$I,E$1,FALSE)*$E8) -> 0 | H8: =IF(ISERROR(VLOOKUP($C7,Database!$A:$I,F$1,FALSE)*$E8),0,VLOOKUP($C7,Database!$A:$I,F$1,FALSE)*$E8) -> 0 | I8: =IF(ISERROR(VLOOKUP($C7,Database!$A:$I,G$1,FALSE)*$E8),0,VLOOKUP($C7,Database!$A:$I,G$1,FALSE)*$E8) -> 0 | J8: =IF(ISERROR(VLOOKUP($C7,Database!$A:$I,H$1,FALSE)*$E8),0,VLOOKUP($C7,Database!$A:$I,H$1,FALSE)*$E8) -> 0 | K8: =IF(ISERROR(VLOOKUP($C7,Database!$A:$I,I$1,FALSE)*$E8),0,VLOOKUP($C7,Database!$A:$I,I$1,FALSE)*$E8) -> 0 | L8: =IF(ISERROR(VLOOKUP($C7,Database!$A:$I,J$1,FALSE)*$E8),0,VLOOKUP($C7,Database!$A:$I,J$1,FALSE)*$E8) -> 0.0008899143 | M8: =IF(ISERROR(VLOOKUP($C7,Database!$A:$I,K$1,FALSE)*$E8),0,VLOOKUP($C7,Database!$A:$I,K$1,FALSE)*$E8) -> 0 | N8: =IF(ISERROR(VLOOKUP($C7,Database!$A:$J,10,FALSE)),0,VLOOKUP($C7,Database!$A:$J,10,FALSE)*$E8) -> 0.0062788398
A9: =#REF! -> #REF! | B9: =Database!A11 -> Barry Blanc Satin | C9: sugar sorbitol | D9: 33 | E9: =D9/$D$30 -> 0.054383652 | F9: =IF(ISERROR(VLOOKUP($C9,Database!$A:$I,D$1,FALSE)*$E9),0,VLOOKUP($C9,Database!$A:$I,D$1,FALSE)*$E9) -> 0.054383652 | G9: =IF(ISERROR(VLOOKUP($C9,Database!$A:$I,E$1,FALSE)*$E9),0,VLOOKUP($C9,Database!$A:$I,E$1,FALSE)*$E9) -> 0 | H9: =IF(ISERROR(VLOOKUP($C9,Database!$A:$I,F$1,FALSE)*$E9),0,VLOOKUP($C9,Database!$A:$I,F$1,FALSE)*$E9) -> 0 | I9: =IF(ISERROR(VLOOKUP($C9,Database!$A:$I,G$1,FALSE)*$E9),0,VLOOKUP($C9,Database!$A:$I,G$1,FALSE)*$E9) -> 0 | J9: =IF(ISERROR(VLOOKUP($C9,Database!$A:$I,H$1,FALSE)*$E9),0,VLOOKUP($C9,Database!$A:$I,H$1,FALSE)*$E9) -> 0 | K9: =IF(ISERROR(VLOOKUP($C9,Database!$A:$I,I$1,FALSE)*$E9),0,VLOOKUP($C9,Database!$A:$I,I$1,FALSE)*$E9) -> 0 | L9: =IF(ISERROR(VLOOKUP($C9,Database!$A:$I,J$1,FALSE)*$E9),0,VLOOKUP($C9,Database!$A:$I,J$1,FALSE)*$E9) -> 0 | M9: =IF(ISERROR(VLOOKUP($C9,Database!$A:$I,K$1,FALSE)*$E9),0,VLOOKUP($C9,Database!$A:$I,K$1,FALSE)*$E9) -> 0 | N9: =IF(ISERROR(VLOOKUP($C9,Database!$A:$J,10,FALSE)),0,VLOOKUP($C9,Database!$A:$J,10,FALSE)*$E9) -> 0.027191826
A10: =#REF! -> #REF! | B10: =Database!A12 -> Barry Cuba | C10: callebaut 823 | D10: 350 | E10: =D10/$D$30 -> 0.57679631 | F10: =IF(ISERROR(VLOOKUP($C10,Database!$A:$I,D$1,FALSE)*$E10),0,VLOOKUP($C10,Database!$A:$I,D$1,FALSE)*$E10) -> 0.24225445 | G10: =IF(ISERROR(VLOOKUP($C10,Database!$A:$I,E$1,FALSE)*$E10),0,VLOOKUP($C10,Database!$A:$I,E$1,FALSE)*$E10) -> 0.034607779 | H10: =IF(ISERROR(VLOOKUP($C10,Database!$A:$I,F$1,FALSE)*$E10),0,VLOOKUP($C10,Database!$A:$I,F$1,FALSE)*$E10) -> 0.17303889 | I10: =IF(ISERROR(VLOOKUP($C10,Database!$A:$I,G$1,FALSE)*$E10),0,VLOOKUP($C10,Database!$A:$I,G$1,FALSE)*$E10) -> 0.095171391 | J10: =IF(ISERROR(VLOOKUP($C10,Database!$A:$I,H$1,FALSE)*$E10),0,VLOOKUP($C10,Database!$A:$I,H$1,FALSE)*$E10) -> 0.017303889 | K10: =IF(ISERROR(VLOOKUP($C10,Database!$A:$I,I$1,FALSE)*$E10),0,VLOOKUP($C10,Database!$A:$I,I$1,FALSE)*$E10) -> 0 | L10: =IF(ISERROR(VLOOKUP($C10,Database!$A:$I,J$1,FALSE)*$E10),0,VLOOKUP($C10,Database!$A:$I,J$1,FALSE)*$E10) -> 0 | M10: =IF(ISERROR(VLOOKUP($C10,Database!$A:$I,K$1,FALSE)*$E10),0,VLOOKUP($C10,Database!$A:$I,K$1,FALSE)*$E10) -> 0 | N10: =IF(ISERROR(VLOOKUP($C10,Database!$A:$J,10,FALSE)),0,VLOOKUP($C10,Database!$A:$J,10,FALSE)*$E10) -> 0.24225445
A11: =#REF! -> #REF! | B11: =Database!A13 -> Barry Excellence | C11: fruit puree вишня | D11: 170 | E11: =D11/$D$30 -> 0.28015821 | F11: =IF(ISERROR(VLOOKUP($C11,Database!$A:$I,D$1,FALSE)*$E11),0,VLOOKUP($C11,Database!$A:$I,D$1,FALSE)*$E11) -> 0.059113382 | G11: =IF(ISERROR(VLOOKUP($C11,Database!$A:$I,E$1,FALSE)*$E11),0,VLOOKUP($C11,Database!$A:$I,E$1,FALSE)*$E11) -> 0 | H11: =IF(ISERROR(VLOOKUP($C11,Database!$A:$I,F$1,FALSE)*$E11),0,VLOOKUP($C11,Database!$A:$I,F$1,FALSE)*$E11) -> 0 | I11: =IF(ISERROR(VLOOKUP($C11,Database!$A:$I,G$1,FALSE)*$E11),0,VLOOKUP($C11,Database!$A:$I,G$1,FALSE)*$E11) -> 0 | J11: =IF(ISERROR(VLOOKUP($C11,Database!$A:$I,H$1,FALSE)*$E11),0,VLOOKUP($C11,Database!$A:$I,H$1,FALSE)*$E11) -> 0 | K11: =IF(ISERROR(VLOOKUP($C11,Database!$A:$I,I$1,FALSE)*$E11),0,VLOOKUP($C11,Database!$A:$I,I$1,FALSE)*$E11) -> 0 | L11: =IF(ISERROR(VLOOKUP($C11,Database!$A:$I,J$1,FALSE)*$E11),0,VLOOKUP($C11,Database!$A:$I,J$1,FALSE)*$E11) -> 0.20479565 | M11: =IF(ISERROR(VLOOKUP($C11,Database!$A:$I,K$1,FALSE)*$E11),0,VLOOKUP($C11,Database!$A:$I,K$1,FALSE)*$E11) -> 0 | N11: =IF(ISERROR(VLOOKUP($C11,Database!$A:$J,10,FALSE)),0,VLOOKUP($C11,Database!$A:$J,10,FALSE)*$E11) -> 0.059113382
A12: =#REF! -> #REF! | B12: =Database!A14 -> Barry Extra bitter | C12: butter fresh | D12: 3 | E12: =D12/$D$30 -> 0.0049439684 | F12: =IF(ISERROR(VLOOKUP($C12,Database!$A:$I,D$1,FALSE)*$E12),0,VLOOKUP($C12,Database!$A:$I,D$1,FALSE)*$E12) -> 0 | G12: =IF(ISERROR(VLOOKUP($C12,Database!$A:$I,E$1,FALSE)*$E12),0,VLOOKUP($C12,Database!$A:$I,E$1,FALSE)*$E12) -> 0.0040540541 | H12: =IF(ISERROR(VLOOKUP($C12,Database!$A:$I,F$1,FALSE)*$E12),0,VLOOKUP($C12,Database!$A:$I,F$1,FALSE)*$E12) -> 0 | I12: =IF(ISERROR(VLOOKUP($C12,Database!$A:$I,G$1,FALSE)*$E12),0,VLOOKUP($C12,Database!$A:$I,G$1,FALSE)*$E12) -> 9.8879367e-05 | J12: =IF(ISERROR(VLOOKUP($C12,Database!$A:$I,H$1,FALSE)*$E12),0,VLOOKUP($C12,Database!$A:$I,H$1,FALSE)*$E12) -> 0 | K12: =IF(ISERROR(VLOOKUP($C12,Database!$A:$I,I$1,FALSE)*$E12),0,VLOOKUP($C12,Database!$A:$I,I$1,FALSE)*$E12) -> 0 | L12: =IF(ISERROR(VLOOKUP($C12,Database!$A:$I,J$1,FALSE)*$E12),0,VLOOKUP($C12,Database!$A:$I,J$1,FALSE)*$E12) -> 0.00079103494 | M12: =IF(ISERROR(VLOOKUP($C12,Database!$A:$I,K$1,FALSE)*$E12),0,VLOOKUP($C12,Database!$A:$I,K$1,FALSE)*$E12) -> 0 | N12: =IF(ISERROR(VLOOKUP($C12,Database!$A:$J,10,FALSE)),0,VLOOKUP($C12,Database!$A:$J,10,FALSE)*$E12) -> 0
A13: =#REF! -> #REF! | B13: =Database!A15 -> Barry Fleur de Cao | D13: 35 | E13: =D13/$D$30 -> 0.057679631 | F13: =IF(ISERROR(VLOOKUP($C13,Database!$A:$I,D$1,FALSE)*$E13),0,VLOOKUP($C13,Database!$A:$I,D$1,FALSE)*$E13) -> 0 | G13: =IF(ISERROR(VLOOKUP($C13,Database!$A:$I,E$1,FALSE)*$E13),0,VLOOKUP($C13,Database!$A:$I,E$1,FALSE)*$E13) -> 0 | H13: =IF(ISERROR(VLOOKUP($C13,Database!$A:$I,F$1,FALSE)*$E13),0,VLOOKUP($C13,Database!$A:$I,F$1,FALSE)*$E13) -> 0 | I13: =IF(ISERROR(VLOOKUP($C13,Database!$A:$I,G$1,FALSE)*$E13),0,VLOOKUP($C13,Database!$A:$I,G$1,FALSE)*$E13) -> 0 | J13: =IF(ISERROR(VLOOKUP($C13,Database!$A:$I,H$1,FALSE)*$E13),0,VLOOKUP($C13,Database!$A:$I,H$1,FALSE)*$E13) -> 0 | K13: =IF(ISERROR(VLOOKUP($C13,Database!$A:$I,I$1,FALSE)*$E13),0,VLOOKUP($C13,Database!$A:$I,I$1,FALSE)*$E13) -> 0 | L13: =IF(ISERROR(VLOOKUP($C13,Database!$A:$I,J$1,FALSE)*$E13),0,VLOOKUP($C13,Database!$A:$I,J$1,FALSE)*$E13) -> 0 | M13: =IF(ISERROR(VLOOKUP($C13,Database!$A:$I,K$1,FALSE)*$E13),0,VLOOKUP($C13,Database!$A:$I,K$1,FALSE)*$E13) -> 0 | N13: =IF(ISERROR(VLOOKUP($C13,Database!$A:$J,10,FALSE)),0,VLOOKUP($C13,Database!$A:$J,10,FALSE)*$E13) -> 0
E14: =D14/$D$30 -> 0 | F14: =IF(ISERROR(VLOOKUP($C14,Database!$A:$I,D$1,FALSE)*$E14),0,VLOOKUP($C14,Database!$A:$I,D$1,FALSE)*$E14) -> 0 | G14: =IF(ISERROR(VLOOKUP($C14,Database!$A:$I,E$1,FALSE)*$E14),0,VLOOKUP($C14,Database!$A:$I,E$1,FALSE)*$E14) -> 0 | H14: =IF(ISERROR(VLOOKUP($C14,Database!$A:$I,F$1,FALSE)*$E14),0,VLOOKUP($C14,Database!$A:$I,F$1,FALSE)*$E14) -> 0 | I14: =IF(ISERROR(VLOOKUP($C14,Database!$A:$I,G$1,FALSE)*$E14),0,VLOOKUP($C14,Database!$A:$I,G$1,FALSE)*$E14) -> 0 | J14: =IF(ISERROR(VLOOKUP($C14,Database!$A:$I,H$1,FALSE)*$E14),0,VLOOKUP($C14,Database!$A:$I,H$1,FALSE)*$E14) -> 0 | K14: =IF(ISERROR(VLOOKUP($C14,Database!$A:$I,I$1,FALSE)*$E14),0,VLOOKUP($C14,Database!$A:$I,I$1,FALSE)*$E14) -> 0 | L14: =IF(ISERROR(VLOOKUP($C14,Database!$A:$I,J$1,FALSE)*$E14),0,VLOOKUP($C14,Database!$A:$I,J$1,FALSE)*$E14) -> 0 | M14: =IF(ISERROR(VLOOKUP($C14,Database!$A:$I,K$1,FALSE)*$E14),0,VLOOKUP($C14,Database!$A:$I,K$1,FALSE)*$E14) -> 0 | N14: =IF(ISERROR(VLOOKUP($C14,Database!$A:$J,10,FALSE)),0,VLOOKUP($C14,Database!$A:$J,10,FALSE)*$E14) -> 0
A15: =#REF! -> #REF! | B15: =Database!A17 -> Barry Lactee Superieure | E15: =D15/$D$30 -> 0 | F15: =IF(ISERROR(VLOOKUP($C15,Database!$A:$I,D$1,FALSE)*$E15),0,VLOOKUP($C15,Database!$A:$I,D$1,FALSE)*$E15) -> 0 | G15: =IF(ISERROR(VLOOKUP($C15,Database!$A:$I,E$1,FALSE)*$E15),0,VLOOKUP($C15,Database!$A:$I,E$1,FALSE)*$E15) -> 0 | H15: =IF(ISERROR(VLOOKUP($C15,Database!$A:$I,F$1,FALSE)*$E15),0,VLOOKUP($C15,Database!$A:$I,F$1,FALSE)*$E15) -> 0 | I15: =IF(ISERROR(VLOOKUP($C15,Database!$A:$I,G$1,FALSE)*$E15),0,VLOOKUP($C15,Database!$A:$I,G$1,FALSE)*$E15) -> 0 | J15: =IF(ISERROR(VLOOKUP($C15,Database!$A:$I,H$1,FALSE)*$E15),0,VLOOKUP($C15,Database!$A:$I,H$1,FALSE)*$E15) -> 0 | K15: =IF(ISERROR(VLOOKUP($C15,Database!$A:$I,I$1,FALSE)*$E15),0,VLOOKUP($C15,Database!$A:$I,I$1,FALSE)*$E15) -> 0 | L15: =IF(ISERROR(VLOOKUP($C15,Database!$A:$I,J$1,FALSE)*$E15),0,VLOOKUP($C15,Database!$A:$I,J$1,FALSE)*$E15) -> 0 | M15: =IF(ISERROR(VLOOKUP($C15,Database!$A:$I,K$1,FALSE)*$E15),0,VLOOKUP($C15,Database!$A:$I,K$1,FALSE)*$E15) -> 0 | N15: =IF(ISERROR(VLOOKUP($C15,Database!$A:$J,10,FALSE)),0,VLOOKUP($C15,Database!$A:$J,10,FALSE)*$E15) -> 0
A16: =#REF! -> #REF! | B16: =Database!A18 -> Barry Mexique | E16: =D16/$D$30 -> 0 | F16: =IF(ISERROR(VLOOKUP($C16,Database!$A:$I,D$1,FALSE)*$E16),0,VLOOKUP($C16,Database!$A:$I,D$1,FALSE)*$E16) -> 0 | G16: =IF(ISERROR(VLOOKUP($C16,Database!$A:$I,E$1,FALSE)*$E16),0,VLOOKUP($C16,Database!$A:$I,E$1,FALSE)*$E16) -> 0 | H16: =IF(ISERROR(VLOOKUP($C16,Database!$A:$I,F$1,FALSE)*$E16),0,VLOOKUP($C16,Database!$A:$I,F$1,FALSE)*$E16) -> 0 | I16: =IF(ISERROR(VLOOKUP($C16,Database!$A:$I,G$1,FALSE)*$E16),0,VLOOKUP($C16,Database!$A:$I,G$1,FALSE)*$E16) -> 0 | J16: =IF(ISERROR(VLOOKUP($C16,Database!$A:$I,H$1,FALSE)*$E16),0,VLOOKUP($C16,Database!$A:$I,H$1,FALSE)*$E16) -> 0 | K16: =IF(ISERROR(VLOOKUP($C16,Database!$A:$I,I$1,FALSE)*$E16),0,VLOOKUP($C16,Database!$A:$I,I$1,FALSE)*$E16) -> 0 | L16: =IF(ISERROR(VLOOKUP($C16,Database!$A:$I,J$1,FALSE)*$E16),0,VLOOKUP($C16,Database!$A:$I,J$1,FALSE)*$E16) -> 0 | M16: =IF(ISERROR(VLOOKUP($C16,Database!$A:$I,K$1,FALSE)*$E16),0,VLOOKUP($C16,Database!$A:$I,K$1,FALSE)*$E16) -> 0 | N16: =IF(ISERROR(VLOOKUP($C16,Database!$A:$J,10,FALSE)),0,VLOOKUP($C16,Database!$A:$J,10,FALSE)*$E16) -> 0
A17: =#REF! -> #REF! | B17: =Database!A19 -> Barry Papouasie | E17: =D17/$D$30 -> 0 | F17: =IF(ISERROR(VLOOKUP($C17,Database!$A:$I,D$1,FALSE)*$E17),0,VLOOKUP($C17,Database!$A:$I,D$1,FALSE)*$E17) -> 0 | G17: =IF(ISERROR(VLOOKUP($C17,Database!$A:$I,E$1,FALSE)*$E17),0,VLOOKUP($C17,Database!$A:$I,E$1,FALSE)*$E17) -> 0 | H17: =IF(ISERROR(VLOOKUP($C17,Database!$A:$I,F$1,FALSE)*$E17),0,VLOOKUP($C17,Database!$A:$I,F$1,FALSE)*$E17) -> 0 | I17: =IF(ISERROR(VLOOKUP($C17,Database!$A:$I,G$1,FALSE)*$E17),0,VLOOKUP($C17,Database!$A:$I,G$1,FALSE)*$E17) -> 0 | J17: =IF(ISERROR(VLOOKUP($C17,Database!$A:$I,H$1,FALSE)*$E17),0,VLOOKUP($C17,Database!$A:$I,H$1,FALSE)*$E17) -> 0 | K17: =IF(ISERROR(VLOOKUP($C17,Database!$A:$I,I$1,FALSE)*$E17),0,VLOOKUP($C17,Database!$A:$I,I$1,FALSE)*$E17) -> 0 | L17: =IF(ISERROR(VLOOKUP($C17,Database!$A:$I,J$1,FALSE)*$E17),0,VLOOKUP($C17,Database!$A:$I,J$1,FALSE)*$E17) -> 0 | M17: =IF(ISERROR(VLOOKUP($C17,Database!$A:$I,K$1,FALSE)*$E17),0,VLOOKUP($C17,Database!$A:$I,K$1,FALSE)*$E17) -> 0 | N17: =IF(ISERROR(VLOOKUP($C17,Database!$A:$J,10,FALSE)),0,VLOOKUP($C17,Database!$A:$J,10,FALSE)*$E17) -> 0
A18: =#REF! -> #REF! | B18: =Database!A20 -> Barry Saint Dominique | E18: =D18/$D$30 -> 0 | F18: =IF(ISERROR(VLOOKUP($C18,Database!$A:$I,D$1,FALSE)*$E18),0,VLOOKUP($C18,Database!$A:$I,D$1,FALSE)*$E18) -> 0 | G18: =IF(ISERROR(VLOOKUP($C18,Database!$A:$I,E$1,FALSE)*$E18),0,VLOOKUP($C18,Database!$A:$I,E$1,FALSE)*$E18) -> 0 | H18: =IF(ISERROR(VLOOKUP($C18,Database!$A:$I,F$1,FALSE)*$E18),0,VLOOKUP($C18,Database!$A:$I,F$1,FALSE)*$E18) -> 0 | I18: =IF(ISERROR(VLOOKUP($C18,Database!$A:$I,G$1,FALSE)*$E18),0,VLOOKUP($C18,Database!$A:$I,G$1,FALSE)*$E18) -> 0 | J18: =IF(ISERROR(VLOOKUP($C18,Database!$A:$I,H$1,FALSE)*$E18),0,VLOOKUP($C18,Database!$A:$I,H$1,FALSE)*$E18) -> 0 | K18: =IF(ISERROR(VLOOKUP($C18,Database!$A:$I,I$1,FALSE)*$E18),0,VLOOKUP($C18,Database!$A:$I,I$1,FALSE)*$E18) -> 0 | L18: =IF(ISERROR(VLOOKUP($C18,Database!$A:$I,J$1,FALSE)*$E18),0,VLOOKUP($C18,Database!$A:$I,J$1,FALSE)*$E18) -> 0 | M18: =IF(ISERROR(VLOOKUP($C18,Database!$A:$I,K$1,FALSE)*$E18),0,VLOOKUP($C18,Database!$A:$I,K$1,FALSE)*$E18) -> 0 | N18: =IF(ISERROR(VLOOKUP($C18,Database!$A:$J,10,FALSE)),0,VLOOKUP($C18,Database!$A:$J,10,FALSE)*$E18) -> 0
A19: =#REF! -> #REF! | B19: =Database!A21 -> Barry Tanzanie | E19: =D19/$D$30 -> 0 | F19: =IF(ISERROR(VLOOKUP($C19,Database!$A:$I,D$1,FALSE)*$E19),0,VLOOKUP($C19,Database!$A:$I,D$1,FALSE)*$E19) -> 0 | G19: =IF(ISERROR(VLOOKUP($C19,Database!$A:$I,E$1,FALSE)*$E19),0,VLOOKUP($C19,Database!$A:$I,E$1,FALSE)*$E19) -> 0 | H19: =IF(ISERROR(VLOOKUP($C19,Database!$A:$I,F$1,FALSE)*$E19),0,VLOOKUP($C19,Database!$A:$I,F$1,FALSE)*$E19) -> 0 | I19: =IF(ISERROR(VLOOKUP($C19,Database!$A:$I,G$1,FALSE)*$E19),0,VLOOKUP($C19,Database!$A:$I,G$1,FALSE)*$E19) -> 0 | J19: =IF(ISERROR(VLOOKUP($C19,Database!$A:$I,H$1,FALSE)*$E19),0,VLOOKUP($C19,Database!$A:$I,H$1,FALSE)*$E19) -> 0 | K19: =IF(ISERROR(VLOOKUP($C19,Database!$A:$I,I$1,FALSE)*$E19),0,VLOOKUP($C19,Database!$A:$I,I$1,FALSE)*$E19) -> 0 | L19: =IF(ISERROR(VLOOKUP($C19,Database!$A:$I,J$1,FALSE)*$E19),0,VLOOKUP($C19,Database!$A:$I,J$1,FALSE)*$E19) -> 0 | M19: =IF(ISERROR(VLOOKUP($C19,Database!$A:$I,K$1,FALSE)*$E19),0,VLOOKUP($C19,Database!$A:$I,K$1,FALSE)*$E19) -> 0 | N19: =IF(ISERROR(VLOOKUP($C19,Database!$A:$J,10,FALSE)),0,VLOOKUP($C19,Database!$A:$J,10,FALSE)*$E19) -> 0
A20: =#REF! -> #REF! | B20: =Database!A22 -> Barry Zephyr | E20: =D20/$D$30 -> 0 | F20: =IF(ISERROR(VLOOKUP($C20,Database!$A:$I,D$1,FALSE)*$E20),0,VLOOKUP($C20,Database!$A:$I,D$1,FALSE)*$E20) -> 0 | G20: =IF(ISERROR(VLOOKUP($C20,Database!$A:$I,E$1,FALSE)*$E20),0,VLOOKUP($C20,Database!$A:$I,E$1,FALSE)*$E20) -> 0 | H20: =IF(ISERROR(VLOOKUP($C20,Database!$A:$I,F$1,FALSE)*$E20),0,VLOOKUP($C20,Database!$A:$I,F$1,FALSE)*$E20) -> 0 | I20: =IF(ISERROR(VLOOKUP($C20,Database!$A:$I,G$1,FALSE)*$E20),0,VLOOKUP($C20,Database!$A:$I,G$1,FALSE)*$E20) -> 0 | J20: =IF(ISERROR(VLOOKUP($C20,Database!$A:$I,H$1,FALSE)*$E20),0,VLOOKUP($C20,Database!$A:$I,H$1,FALSE)*$E20) -> 0 | K20: =IF(ISERROR(VLOOKUP($C20,Database!$A:$I,I$1,FALSE)*$E20),0,VLOOKUP($C20,Database!$A:$I,I$1,FALSE)*$E20) -> 0 | L20: =IF(ISERROR(VLOOKUP($C20,Database!$A:$I,J$1,FALSE)*$E20),0,VLOOKUP($C20,Database!$A:$I,J$1,FALSE)*$E20) -> 0 | M20: =IF(ISERROR(VLOOKUP($C20,Database!$A:$I,K$1,FALSE)*$E20),0,VLOOKUP($C20,Database!$A:$I,K$1,FALSE)*$E20) -> 0 | N20: =IF(ISERROR(VLOOKUP($C20,Database!$A:$J,10,FALSE)),0,VLOOKUP($C20,Database!$A:$J,10,FALSE)*$E20) -> 0
A21: =#REF! -> #REF! | B21: =Database!A23 -> bergamote | E21: =D21/$D$30 -> 0 | F21: =IF(ISERROR(VLOOKUP($C21,Database!$A:$I,D$1,FALSE)*$E21),0,VLOOKUP($C21,Database!$A:$I,D$1,FALSE)*$E21) -> 0 | G21: =IF(ISERROR(VLOOKUP($C21,Database!$A:$I,E$1,FALSE)*$E21),0,VLOOKUP($C21,Database!$A:$I,E$1,FALSE)*$E21) -> 0 | H21: =IF(ISERROR(VLOOKUP($C21,Database!$A:$I,F$1,FALSE)*$E21),0,VLOOKUP($C21,Database!$A:$I,F$1,FALSE)*$E21) -> 0 | I21: =IF(ISERROR(VLOOKUP($C21,Database!$A:$I,G$1,FALSE)*$E21),0,VLOOKUP($C21,Database!$A:$I,G$1,FALSE)*$E21) -> 0 | J21: =IF(ISERROR(VLOOKUP($C21,Database!$A:$I,H$1,FALSE)*$E21),0,VLOOKUP($C21,Database!$A:$I,H$1,FALSE)*$E21) -> 0 | K21: =IF(ISERROR(VLOOKUP($C21,Database!$A:$I,I$1,FALSE)*$E21),0,VLOOKUP($C21,Database!$A:$I,I$1,FALSE)*$E21) -> 0 | L21: =IF(ISERROR(VLOOKUP($C21,Database!$A:$I,J$1,FALSE)*$E21),0,VLOOKUP($C21,Database!$A:$I,J$1,FALSE)*$E21) -> 0 | M21: =IF(ISERROR(VLOOKUP($C21,Database!$A:$I,K$1,FALSE)*$E21),0,VLOOKUP($C21,Database!$A:$I,K$1,FALSE)*$E21) -> 0 | N21: =IF(ISERROR(VLOOKUP($C21,Database!$A:$J,10,FALSE)),0,VLOOKUP($C21,Database!$A:$J,10,FALSE)*$E21) -> 0
A22: =#REF! -> #REF! | B22: =Database!A24 -> butter noisette | E22: =D22/$D$30 -> 0 | F22: =IF(ISERROR(VLOOKUP($C22,Database!$A:$I,D$1,FALSE)*$E22),0,VLOOKUP($C22,Database!$A:$I,D$1,FALSE)*$E22) -> 0 | G22: =IF(ISERROR(VLOOKUP($C22,Database!$A:$I,E$1,FALSE)*$E22),0,VLOOKUP($C22,Database!$A:$I,E$1,FALSE)*$E22) -> 0 | H22: =IF(ISERROR(VLOOKUP($C22,Database!$A:$I,F$1,FALSE)*$E22),0,VLOOKUP($C22,Database!$A:$I,F$1,FALSE)*$E22) -> 0 | I22: =IF(ISERROR(VLOOKUP($C22,Database!$A:$I,G$1,FALSE)*$E22),0,VLOOKUP($C22,Database!$A:$I,G$1,FALSE)*$E22) -> 0 | J22: =IF(ISERROR(VLOOKUP($C22,Database!$A:$I,H$1,FALSE)*$E22),0,VLOOKUP($C22,Database!$A:$I,H$1,FALSE)*$E22) -> 0 | K22: =IF(ISERROR(VLOOKUP($C22,Database!$A:$I,I$1,FALSE)*$E22),0,VLOOKUP($C22,Database!$A:$I,I$1,FALSE)*$E22) -> 0 | L22: =IF(ISERROR(VLOOKUP($C22,Database!$A:$I,J$1,FALSE)*$E22),0,VLOOKUP($C22,Database!$A:$I,J$1,FALSE)*$E22) -> 0 | M22: =IF(ISERROR(VLOOKUP($C22,Database!$A:$I,K$1,FALSE)*$E22),0,VLOOKUP($C22,Database!$A:$I,K$1,FALSE)*$E22) -> 0 | N22: =IF(ISERROR(VLOOKUP($C22,Database!$A:$J,10,FALSE)),0,VLOOKUP($C22,Database!$A:$J,10,FALSE)*$E22) -> 0
A23: =#REF! -> #REF! | B23: =Database!A25 -> butter anhydrous 28 | E23: =D23/$D$30 -> 0 | F23: =IF(ISERROR(VLOOKUP($C23,Database!$A:$I,D$1,FALSE)*$E23),0,VLOOKUP($C23,Database!$A:$I,D$1,FALSE)*$E23) -> 0 | G23: =IF(ISERROR(VLOOKUP($C23,Database!$A:$I,E$1,FALSE)*$E23),0,VLOOKUP($C23,Database!$A:$I,E$1,FALSE)*$E23) -> 0 | H23: =IF(ISERROR(VLOOKUP($C23,Database!$A:$I,F$1,FALSE)*$E23),0,VLOOKUP($C23,Database!$A:$I,F$1,FALSE)*$E23) -> 0 | I23: =IF(ISERROR(VLOOKUP($C23,Database!$A:$I,G$1,FALSE)*$E23),0,VLOOKUP($C23,Database!$A:$I,G$1,FALSE)*$E23) -> 0 | J23: =IF(ISERROR(VLOOKUP($C23,Database!$A:$I,H$1,FALSE)*$E23),0,VLOOKUP($C23,Database!$A:$I,H$1,FALSE)*$E23) -> 0 | K23: =IF(ISERROR(VLOOKUP($C23,Database!$A:$I,I$1,FALSE)*$E23),0,VLOOKUP($C23,Database!$A:$I,I$1,FALSE)*$E23) -> 0 | L23: =IF(ISERROR(VLOOKUP($C23,Database!$A:$I,J$1,FALSE)*$E23),0,VLOOKUP($C23,Database!$A:$I,J$1,FALSE)*$E23) -> 0 | M23: =IF(ISERROR(VLOOKUP($C23,Database!$A:$I,K$1,FALSE)*$E23),0,VLOOKUP($C23,Database!$A:$I,K$1,FALSE)*$E23) -> 0 | N23: =IF(ISERROR(VLOOKUP($C23,Database!$A:$J,10,FALSE)),0,VLOOKUP($C23,Database!$A:$J,10,FALSE)*$E23) -> 0
A24: =#REF! -> #REF! | B24: =Database!A26 -> butter cacao | E24: =D24/$D$30 -> 0 | F24: =IF(ISERROR(VLOOKUP($C24,Database!$A:$I,D$1,FALSE)*$E24),0,VLOOKUP($C24,Database!$A:$I,D$1,FALSE)*$E24) -> 0 | G24: =IF(ISERROR(VLOOKUP($C24,Database!$A:$I,E$1,FALSE)*$E24),0,VLOOKUP($C24,Database!$A:$I,E$1,FALSE)*$E24) -> 0 | H24: =IF(ISERROR(VLOOKUP($C24,Database!$A:$I,F$1,FALSE)*$E24),0,VLOOKUP($C24,Database!$A:$I,F$1,FALSE)*$E24) -> 0 | I24: =IF(ISERROR(VLOOKUP($C24,Database!$A:$I,G$1,FALSE)*$E24),0,VLOOKUP($C24,Database!$A:$I,G$1,FALSE)*$E24) -> 0 | J24: =IF(ISERROR(VLOOKUP($C24,Database!$A:$I,H$1,FALSE)*$E24),0,VLOOKUP($C24,Database!$A:$I,H$1,FALSE)*$E24) -> 0 | K24: =IF(ISERROR(VLOOKUP($C24,Database!$A:$I,I$1,FALSE)*$E24),0,VLOOKUP($C24,Database!$A:$I,I$1,FALSE)*$E24) -> 0 | L24: =IF(ISERROR(VLOOKUP($C24,Database!$A:$I,J$1,FALSE)*$E24),0,VLOOKUP($C24,Database!$A:$I,J$1,FALSE)*$E24) -> 0 | M24: =IF(ISERROR(VLOOKUP($C24,Database!$A:$I,K$1,FALSE)*$E24),0,VLOOKUP($C24,Database!$A:$I,K$1,FALSE)*$E24) -> 0 | N24: =IF(ISERROR(VLOOKUP($C24,Database!$A:$J,10,FALSE)),0,VLOOKUP($C24,Database!$A:$J,10,FALSE)*$E24) -> 0
A25: =#REF! -> #REF! | B25: =Database!A27 -> butter fresh | E25: =D25/$D$30 -> 0 | F25: =IF(ISERROR(VLOOKUP($C25,Database!$A:$I,D$1,FALSE)*$E25),0,VLOOKUP($C25,Database!$A:$I,D$1,FALSE)*$E25) -> 0 | G25: =IF(ISERROR(VLOOKUP($C25,Database!$A:$I,E$1,FALSE)*$E25),0,VLOOKUP($C25,Database!$A:$I,E$1,FALSE)*$E25) -> 0 | H25: =IF(ISERROR(VLOOKUP($C25,Database!$A:$I,F$1,FALSE)*$E25),0,VLOOKUP($C25,Database!$A:$I,F$1,FALSE)*$E25) -> 0 | I25: =IF(ISERROR(VLOOKUP($C25,Database!$A:$I,G$1,FALSE)*$E25),0,VLOOKUP($C25,Database!$A:$I,G$1,FALSE)*$E25) -> 0 | J25: =IF(ISERROR(VLOOKUP($C25,Database!$A:$I,H$1,FALSE)*$E25),0,VLOOKUP($C25,Database!$A:$I,H$1,FALSE)*$E25) -> 0 | K25: =IF(ISERROR(VLOOKUP($C25,Database!$A:$I,I$1,FALSE)*$E25),0,VLOOKUP($C25,Database!$A:$I,I$1,FALSE)*$E25) -> 0 | L25: =IF(ISERROR(VLOOKUP($C25,Database!$A:$I,J$1,FALSE)*$E25),0,VLOOKUP($C25,Database!$A:$I,J$1,FALSE)*$E25) -> 0 | M25: =IF(ISERROR(VLOOKUP($C25,Database!$A:$I,K$1,FALSE)*$E25),0,VLOOKUP($C25,Database!$A:$I,K$1,FALSE)*$E25) -> 0 | N25: =IF(ISERROR(VLOOKUP($C25,Database!$A:$J,10,FALSE)),0,VLOOKUP($C25,Database!$A:$J,10,FALSE)*$E25) -> 0
A26: =#REF! -> #REF! | B26: =Database!A28 -> cacao-barry Excellence | E26: =D26/$D$30 -> 0 | F26: =IF(ISERROR(VLOOKUP($C26,Database!$A:$I,D$1,FALSE)*$E26),0,VLOOKUP($C26,Database!$A:$I,D$1,FALSE)*$E26) -> 0 | G26: =IF(ISERROR(VLOOKUP($C26,Database!$A:$I,E$1,FALSE)*$E26),0,VLOOKUP($C26,Database!$A:$I,E$1,FALSE)*$E26) -> 0 | H26: =IF(ISERROR(VLOOKUP($C26,Database!$A:$I,F$1,FALSE)*$E26),0,VLOOKUP($C26,Database!$A:$I,F$1,FALSE)*$E26) -> 0 | I26: =IF(ISERROR(VLOOKUP($C26,Database!$A:$I,G$1,FALSE)*$E26),0,VLOOKUP($C26,Database!$A:$I,G$1,FALSE)*$E26) -> 0 | J26: =IF(ISERROR(VLOOKUP($C26,Database!$A:$I,H$1,FALSE)*$E26),0,VLOOKUP($C26,Database!$A:$I,H$1,FALSE)*$E26) -> 0 | K26: =IF(ISERROR(VLOOKUP($C26,Database!$A:$I,I$1,FALSE)*$E26),0,VLOOKUP($C26,Database!$A:$I,I$1,FALSE)*$E26) -> 0 | L26: =IF(ISERROR(VLOOKUP($C26,Database!$A:$I,J$1,FALSE)*$E26),0,VLOOKUP($C26,Database!$A:$I,J$1,FALSE)*$E26) -> 0 | M26: =IF(ISERROR(VLOOKUP($C26,Database!$A:$I,K$1,FALSE)*$E26),0,VLOOKUP($C26,Database!$A:$I,K$1,FALSE)*$E26) -> 0 | N26: =IF(ISERROR(VLOOKUP($C26,Database!$A:$J,10,FALSE)),0,VLOOKUP($C26,Database!$A:$J,10,FALSE)*$E26) -> 0
... A29: =#REF! -> #REF! | B29: =Database!A31 -> callebaut 811 | E29: =D29/$D$30 -> 0 | F29: =IF(ISERROR(VLOOKUP($C29,Database!$A:$I,D$1,FALSE)*$E29),0,VLOOKUP($C29,Database!$A:$I,D$1,FALSE)*$E29) -> 0 | G29: =IF(ISERROR(VLOOKUP($C29,Database!$A:$I,E$1,FALSE)*$E29),0,VLOOKUP($C29,Database!$A:$I,E$1,FALSE)*$E29) -> 0 | H29: =IF(ISERROR(VLOOKUP($C29,Database!$A:$I,F$1,FALSE)*$E29),0,VLOOKUP($C29,Database!$A:$I,F$1,FALSE)*$E29) -> 0 | I29: =IF(ISERROR(VLOOKUP($C29,Database!$A:$I,G$1,FALSE)*$E29),0,VLOOKUP($C29,Database!$A:$I,G$1,FALSE)*$E29) -> 0 | J29: =IF(ISERROR(VLOOKUP($C29,Database!$A:$I,H$1,FALSE)*$E29),0,VLOOKUP($C29,Database!$A:$I,H$1,FALSE)*$E29) -> 0 | K29: =IF(ISERROR(VLOOKUP($C29,Database!$A:$I,I$1,FALSE)*$E29),0,VLOOKUP($C29,Database!$A:$I,I$1,FALSE)*$E29) -> 0 | L29: =IF(ISERROR(VLOOKUP($C29,Database!$A:$I,J$1,FALSE)*$E29),0,VLOOKUP($C29,Database!$A:$I,J$1,FALSE)*$E29) -> 0 | M29: =IF(ISERROR(VLOOKUP($C29,Database!$A:$I,K$1,FALSE)*$E29),0,VLOOKUP($C29,Database!$A:$I,K$1,FALSE)*$E29) -> 0 | N29: =IF(ISERROR(VLOOKUP($C29,Database!$A:$J,10,FALSE)),0,VLOOKUP($C29,Database!$A:$J,10,FALSE)*$E29) -> 0
A30: =#REF! -> #REF! | B30: =Database!A32 -> callebaut 823 | C30: общий вес | D30: =SUM(D5:D29) -> 606.8 | E30: =SUM(E5:E29) -> 1 | F30: =SUM(F5:F29) -> 0.35980554 | G30: =SUM(G5:G29) -> 0.045187871 | H30: =SUM(H5:H29) -> 0.17303889 | I30: =SUM(I5:I29) -> 0.095764667 | J30: =SUM(J5:J29) -> 0.017303889 | K30: =SUM(K5:K29) -> 0 | ... N30: =SUM(N5:N29) -> 0.3348385
A31: =#REF! -> #REF! | B31: =Database!A33 -> callebaut arriba | L31: за кг | M31: =(M30/D30)*1000 -> 0
A32: =#REF! -> #REF! | B32: =Database!A34 -> callebaut cocoa massa | C32: колво порций | D32: 1
A33: =#REF! -> #REF! | B33: =Database!A35 -> callebaut equateur | C33: цена за шт | D33: =$M$30/$D$32 -> 0
A34: =#REF! -> #REF! | B34: =Database!A36 -> callebaut madagascar
A35: =#REF! -> #REF! | B35: =Database!A37 -> callebaut sao thomé | C35: о рецепте
A36: =#REF! -> #REF! | B36: =Database!A38 -> callebaut velvet | C36: общие жиры | D36: =G30+H30 -> 0.21822676
A37: =#REF! -> #REF! | B37: =Database!A39 -> callebaut W2 | C37: сахара | D37: =F30 -> 0.35980554
A38: =#REF! -> #REF! | B38: =Database!A40 -> cream 35% | C38: обш какао | D38: =J30 -> 0.017303889
A39: =#REF! -> #REF! | B39: =Database!A41 -> cream 38% | C39: общ молочные сухие | D39: =I30 -> 0.095764667
C40: прочие сухие | D40: =K30 -> 0
A41: =#REF! -> #REF! | B41: =Database!A42 -> fruit puree абрикос | C41: вода | D41: =L30 -> 0.21859921
A42: =#REF! -> #REF! | B42: =Database!A43 -> fruit puree облепиха
...

Sheet page print
A2: =G31/calculator!D30 -> 0.65919578
B4: =calculator!C3 -> 0
B6: название
B11: ингредиенты | F11: единицы | G11: вес | H11: процент
B12: =calculator!C5 -> 0 | F12: g. | G12: =$A$2*calculator!D5 -> 0 | H12: =G12/$G$31 -> 0
B13: =calculator!C6 -> Сливки 33% | F13: g. | G13: =$A$2*calculator!D6 -> 7.9103494 | H13: =G13/$G$31 -> 0.019775873
B14: =calculator!#REF! -> #REF! | F14: g. | G14: =$A$2*calculator!D7 -> 0.52735662 | H14: =G14/$G$31 -> 0.0013183916
B15: =calculator!C7 -> sugar inverted | F15: g. | G15: =$A$2*calculator!D8 -> 1.9775873 | H15: =G15/$G$31 -> 0.0049439684
B16: =calculator!C9 -> sugar sorbitol | F16: g. | G16: =$A$2*calculator!D9 -> 21.753461 | H16: =G16/$G$31 -> 0.054383652
B17: =calculator!C10 -> callebaut 823 | F17: g. | G17: =$A$2*calculator!D10 -> 230.71852 | H17: =G17/$G$31 -> 0.57679631
B18: =calculator!C11 -> fruit puree вишня | F18: g. | G18: =$A$2*calculator!D11 -> 112.06328 | H18: =G18/$G$31 -> 0.28015821
B19: =calculator!C12 -> butter fresh | F19: g. | G19: =$A$2*calculator!D12 -> 1.9775873 | H19: =G19/$G$31 -> 0.0049439684
B20: =calculator!C13 -> 0 | F20: g. | G20: =$A$2*calculator!D13 -> 23.071852 | H20: =G20/$G$31 -> 0.057679631
B21: =calculator!C14 -> 0 | F21: g. | G21: =$A$2*calculator!D14 -> 0 | H21: =G21/$G$31 -> 0
B22: =calculator!C15 -> 0 | F22: g. | G22: =$A$2*calculator!D15 -> 0 | H22: =G22/$G$31 -> 0
B23: =calculator!C16 -> 0 | F23: g. | G23: =$A$2*calculator!D16 -> 0 | H23: =G23/$G$31 -> 0
B24: =calculator!C17 -> 0 | F24: g. | G24: =$A$2*calculator!D17 -> 0 | H24: =G24/$G$31 -> 0
B25: =calculator!C18 -> 0 | F25: g. | G25: =$A$2*calculator!D18 -> 0 | H25: =G25/$G$31 -> 0
C31: общее | G31: 400
C32: стоимость | G32: =$G$31*calculator!$M$30/calculator!$D$30 -> 0
C33: за шт | G33: 0
C34: за шт | D34: за штуку | G34: =$G$32/$G$33 -> #DIV/0!
B38: пометки
